Workbook

Sheet Read Me
A1: BEFORE BONDI — Free Asset List ($0 budget)
A2: Companion to Before_Bondi_Full_Production_Script.pdf. Every ID here matches the 'Assets' line of a segment (S01–S46) in the script.
A4: HOW TO USE
A5: 1. Collect tab by tab. Save each file with the exact name in the 'File name' column so the pipeline can match it automatically.
A6: 2. Edit only the yellow columns: Status (dropdown), Credit line (copy it from the source page), Notes.
A7: 3. If an item can't be found free, use its FREE SWAP fallback. Never pay for anything — the Cost column must stay $0.
A8: 4. Maps and evidence cards are built by the pipeline; they're listed so you can check the source wording.
A9: 5. Voiceover tab: one Grok file per segment. Atlas speaks every odd segment and Ara every even one; their word counts are balanced (see Summary).
A10: 6. Quote Cards: built by the pipeline; open the primary source listed to confirm the exact words before export.
A12: KEY
A13: 🟢 free real footage or photo · FREE SWAP built / stock / AI · 🟡 free only with written permission or confirmed terms (fallback listed)
A14: STATUS
... A18: No graphic content. No AI likeness of real people. No AI religious dress, symbols or flags. Victims' photos only with family permission. Credit every 🟢 item exactly as its source page asks.

Sheet Summary
A1: Category | B1: Total items | C1: Downloaded or further | D1: In repo | E1: % collected | F1: Total cost ($)
A2: Real Footage | B2: =COUNTA('Real Footage'!A2:A7) -> 6 | C2: =COUNTIF('Real Footage'!L2:L7,"Downloaded")+COUNTIF('Real Footage'!L2:L7,"Licence noted")+COUNTIF('Real Footage'!L2:L7,"In repo") -> 0 | D2: =COUNTIF('Real Footage'!L2:L7,"In repo") -> 0 | E2: =IF(B2=0,0,C2/B2) -> 0 | F2: =SUM('Real Footage'!K2:K7) -> 0
A3: Photos | B3: =COUNTA(Photos!A2:A22) -> 21 | C3: =COUNTIF(Photos!L2:L22,"Downloaded")+COUNTIF(Photos!L2:L22,"Licence noted")+COUNTIF(Photos!L2:L22,"In repo") -> 0 | D3: =COUNTIF(Photos!L2:L22,"In repo") -> 0 | E3: =IF(B3=0,0,C3/B3) -> 0 | F3: =SUM(Photos!K2:K22) -> 0
A4: Free Stock | B4: =COUNTA('Free Stock'!A2:A17) -> 16 | C4: =COUNTIF('Free Stock'!L2:L17,"Downloaded")+COUNTIF('Free Stock'!L2:L17,"Licence noted")+COUNTIF('Free Stock'!L2:L17,"In repo") -> 0 | D4: =COUNTIF('Free Stock'!L2:L17,"In repo") -> 0 | E4: =IF(B4=0,0,C4/B4) -> 0 | F4: =SUM('Free Stock'!K2:K17) -> 0
A5: AI B-roll | B5: =COUNTA('AI B-roll'!A2:A11) -> 10 | C5: =COUNTIF('AI B-roll'!L2:L11,"Downloaded")+COUNTIF('AI B-roll'!L2:L11,"Licence noted")+COUNTIF('AI B-roll'!L2:L11,"In repo") -> 0 | D5: =COUNTIF('AI B-roll'!L2:L11,"In repo") -> 0 | E5: =IF(B5=0,0,C5/B5) -> 0 | F5: =SUM('AI B-roll'!K2:K11) -> 0
A6: Quote Cards | B6: =COUNTA('Quote Cards'!A2:A13) -> 12 | C6: =COUNTIF('Quote Cards'!L2:L13,"Downloaded")+COUNTIF('Quote Cards'!L2:L13,"Licence noted")+COUNTIF('Quote Cards'!L2:L13,"In repo") -> 0 | D6: =COUNTIF('Quote Cards'!L2:L13,"In repo") -> 0 | E6: =IF(B6=0,0,C6/B6) -> 0 | F6: =SUM('Quote Cards'!K2:K13) -> 0
A7: Evidence Cards | B7: =COUNTA('Evidence Cards'!A2:A22) -> 21 | C7: =COUNTIF('Evidence Cards'!L2:L22,"Downloaded")+COUNTIF('Evidence Cards'!L2:L22,"Licence noted")+COUNTIF('Evidence Cards'!L2:L22,"In repo") -> 0 | D7: =COUNTIF('Evidence Cards'!L2:L22,"In repo") -> 0 | E7: =IF(B7=0,0,C7/B7) -> 0 | F7: =SUM('Evidence Cards'!K2:K22) -> 0
A8: Maps | B8: =COUNTA(Maps!A2:A13) -> 12 | C8: =COUNTIF(Maps!L2:L13,"Downloaded")+COUNTIF(Maps!L2:L13,"Licence noted")+COUNTIF(Maps!L2:L13,"In repo") -> 0 | D8: =COUNTIF(Maps!L2:L13,"In repo") -> 0 | E8: =IF(B8=0,0,C8/B8) -> 0 | F8: =SUM(Maps!K2:K13) -> 0
A9: Music | B9: =COUNTA(Music!A2:A10) -> 9 | C9: =COUNTIF(Music!L2:L10,"Downloaded")+COUNTIF(Music!L2:L10,"Licence noted")+COUNTIF(Music!L2:L10,"In repo") -> 0 | D9: =COUNTIF(Music!L2:L10,"In repo") -> 0 | E9: =IF(B9=0,0,C9/B9) -> 0 | F9: =SUM(Music!K2:K10) -> 0
A10: SFX | B10: =COUNTA(SFX!A2:A23) -> 22 | C10: =COUNTIF(SFX!L2:L23,"Downloaded")+COUNTIF(SFX!L2:L23,"Licence noted")+COUNTIF(SFX!L2:L23,"In repo") -> 0 | D10: =COUNTIF(SFX!L2:L23,"In repo") -> 0 | E10: =IF(B10=0,0,C10/B10) -> 0 | F10: =SUM(SFX!K2:K23) -> 0
A11: Voiceover | B11: =COUNTA(Voiceover!A2:A47) -> 46 | C11: =COUNTIF(Voiceover!L2:L47,"Downloaded")+COUNTIF(Voiceover!L2:L47,"Licence noted")+COUNTIF(Voiceover!L2:L47,"In repo") -> 0 | D11: =COUNTIF(Voiceover!L2:L47,"In repo") -> 0 | E11: =IF(B11=0,0,C11/B11) -> 0 | F11: =SUM(Voiceover!K2:K47) -> 0
A12: TOTAL | B12: =SUM(B2:B11) -> 175 | C12: =SUM(C2:C11) -> 0 | D12: =SUM(D2:D11) -> 0 | E12: =IF(B12=0,0,C12/B12) -> 0 | F12: =SUM(F2:F11) -> 0
A14: Counts update automatically from each tab's Status column. Total cost must stay $0.
A16: VOICE BALANCE
A17: Atlas words | B17: 891
A18: Ara words | B18: 884
A19: Atlas share | B19: =B17/(B17+B18) -> 0.50197183

Sheet Segment Index
A1: Segment | B1: Starts (approx) | C1: Chapter | D1: Voice | E1: Delivery | F1: Narration (spoken text) | G1: Assets needed | H1: Mid-roll after?
A2: S01 | B2: 0:00 | C2: COLD OPEN: How Did This Happen Here? | D2: Atlas | E2: quiet, grave, unhurried | F2: Bondi Beach. · On the fourteenth of December, twenty twenty-five, the first night of Hanukkah, it became the scene of the deadliest terror attack ever carried out on Australian soil. · Fifteen people were killed. | G2: ST02, SFX13, MG01, SFX24, PH22, MUS10
A3: S02 | B3: 0:19 | C3: COLD OPEN: How Did This Happen Here? | D3: Ara | E3: searching, clear | F3: Afterwards, the whole country asked the same question. · How did this happen here? · Police say the gunmen were inspired by Islamic State. But the Australia they struck had been under strain for two years, ever since the war in Gaza began in October twenty twenty-three. | G3: PH22, PH16, PH17, PH24, ST05, ST09, ST12, DOC02, ST13, MG01, SFX21, SFX05, SFX24, SFX06, MUS10
A4: S03 | B4: 0:38 | C4: COLD OPEN: How Did This Happen Here? | D4: Atlas | E4: leaning in, conspiratorial | F4: This film follows the threads of that strain. · Some go back seventy-eight years. · One goes back just fourteen months, to a fire · in the same suburb. | G4: MAP01, ST16, SFX05, SFX14, SFX24, SFX02, MUS01
A5: S04 | B5: 0:50 | C5: COLD OPEN: How Did This Happen Here? | D5: Ara | E5: quiet, then a chill | F5: October, twenty twenty-four. In the early hours, a small kosher restaurant in Bondi goes up in flames. Nobody is hurt. Police treat it as a local crime. · Seven weeks later, eight hundred kilometres south, a synagogue in Melbourne is firebombed before dawn. | G5: ST03, AI01, PH21, MAP11, PH20, MG01, SFX24, SFX02, SFX03, SFX05, SFX11, MUS01
A6: S05 | B6: 1:08 | C6: COLD OPEN: How Did This Happen Here? | D6: Atlas | E6: hushed, ominous | F6: What almost nobody knew then was that the people who lit these fires were allegedly paid. · And the money trail led to a government on the other side of the world. | G6: AI02, SFX19, SFX21, MUS01
A7: S06 | B7: 1:21 | C7: COLD OPEN: How Did This Happen Here? | D7: Ara | E7: warm, intriguing | F7: And on the night of the attack, one man ran toward the gunfire. · His story became one of the most shared in the country. · We'll come back to him. | G7: ST01, SFX21, MUS01
A8: S07 | B8: 1:34 | C8: COLD OPEN: How Did This Happen Here? | D8: Atlas | E8: calm, setting the contract with the viewer | F8: None of these threads explains Bondi on its own. · But together, they show the country it happened in. · And to understand that country, we have to follow the money first. | G8: MAP01, SFX05, SFX11, MUS12
A9: S08 | B9: 1:54 | C9: CHAPTER 1: The Fire | D9: Ara | E9: investigative, vivid | F9: For months, the fires looked like local crime. But Australia's domestic spy agency, ASIO, kept following the money. · What its investigators found, ASIO's chief later described as a layer cake. | G9: PH24, QT12, MUS12, MUS04, SFX06, SFX21, MG01
A10: S09 | B10: 2:09 | C10: CHAPTER 1: The Fire | D10: Atlas | E10: clear, rhythmic | F10: Middlemen overseas. Coordinators. And at the bottom, local criminals, paid to do a job, not to make a point. · Security experts call it crime as a service. · It's cheap. It's deniable. And it's very hard to detect. | G10: MAP06, SFX06, SFX05, MUS04
A11: S10 | B11: 2:25 | C11: CHAPTER 1: The Fire | D11: Ara | E11: formal, then weighty | F11: August, twenty twenty-five. The Prime Minister announces ASIO's assessment. · According to ASIO, Iran's Islamic Revolutionary Guard Corps directed at least two of the attacks. The Bondi restaurant fire, and the Melbourne synagogue. · He called them, quote, extraordinary and dangerous acts of aggression, orchestrated by a foreign nation on Australian soil. | G11: DOC03, PH21, PH20, QT01, PH07, MG01, MG02, SFX24, SFX11, SFX21, SFX19, MUS04
A12: S11 | B12: 2:47 | C12: CHAPTER 1: The Fire | D12: Atlas | E12: grave, then pointed | F12: Australia expelled Iran's ambassador. The first expulsion of an ambassador since the Second World War. Iran denied any involvement. · In Parliament, Opposition Leader Sussan Ley said the attacks aimed to, quote, turn neighbour against neighbour, and Australian against Australian. · Remember those words. | G12: AI07, DOC19, FT07, QT02, PH29, MG02, SFX22, SFX06, SFX19, SFX21, MUS04
A13: S12 | B13: 3:05 | C13: CHAPTER 1: The Fire | D13: Ara | E13: turning, building a bridge | F13: That was one hundred and ten days before Bondi. · But why would anyone use a fire in Bondi as a weapon at all? · To answer that, we have to go back to a vote Australia cast first. | G13: MAP01, MG01, ST16, SFX24, SFX02, SFX07, MUS04 | H13: YES
A14: S13 | B14: 3:21 | C14: CHAPTER 2: Two Memories | D14: Atlas | E14: storytelling, quiet surprise | F14: November, nineteen forty-seven. The new United Nations votes on a plan to divide Palestine into a Jewish state and an Arab state. · The committee behind it is chaired by Australia's foreign minister. · And the first country to vote yes · is Australia. | G14: PH26, FT05, DOC01, MAP03, DOC02, MG01, MUS12, MUS02, SFX07, SFX24, SFX05, SFX20
A15: S14 | B15: 3:43 | C15: CHAPTER 2: Two Memories | D15: Ara | E15: warm, vivid | F15: Thirty years earlier, Australian Light Horsemen had charged at Beersheba, helping open the road to Jerusalem. · So Australians shaped this land twice. · Once on horseback. And once at a ballot. | G15: ST06, AI03, FT02, PH02, MAP02, DOC02, SFX21, SFX24, SFX16, SFX19, MUS02
A16: S15 | B16: 3:58 | C16: CHAPTER 2: Two Memories | D16: Atlas | E16: soft, even, equal weight to both halves | F16: For many Jewish people, that vote is remembered as a rescue, after the Holocaust. · For Palestinians, what followed in nineteen forty-eight is remembered as the Nakba. The catastrophe. When more than seven hundred thousand people fled or were expelled from their homes. · The same event. · Remembered in two opposite ways. | G16: PH03, PH04, MUS06, SFX21
A17: S16 | B17: 4:22 | C17: CHAPTER 2: Two Memories | D17: Ara | E17: warm, grounded | F17: Both memories sailed to Australia. · Melbourne became home to one of the largest communities of Holocaust survivors, per person, outside Israel. Palestinian, Lebanese and other Arab families settled in Sydney's south-west. · Today, more than one hundred thousand Jewish Australians, and more than eight hundred thousand Muslim Australians, call this country home. | G17: AI05, PH05, PH06, MAP04, DOC10, SFX05, SFX06, MUS02
A18: S17 | B18: 4:43 | C18: CHAPTER 2: Two Memories | D18: Atlas | E18: connecting, forward hook | F18: So when war comes to the Middle East, it doesn't stay there. · It arrives in Australian homes, as family. · And in the two years before Bondi, it arrived in Canberra too. | G18: ST03, MAP01, MG01, SFX05, SFX24, SFX06, MUS07
A19: S18 | B19: 4:57 | C19: CHAPTER 3: Canberra's Choices | D19: Ara | E19: clear, a small reveal | F19: First, a choice almost nobody noticed. · Dozens of Australian companies make parts for the F-35 fighter jet, and those parts go into a shared global pool. · Australia's air force flies the F-35. · So does Israel's. | G19: ST07, AI04, FT01, MAP05, SFX10, SFX19, SFX05, SFX06, SFX09, MUS12, MUS07
A20: S19 | B20: 5:15 | C20: CHAPTER 3: Canberra's Choices | D20: Atlas | E20: neutral, both cases in identical tone | F20: Critics, including aid groups and the Greens, say that makes Australia part of the war. · The government says Australia has not supplied weapons or ammunition to Israel since the war began, and that leaving the pool would weaken Australia's own defence, without grounding a single Israeli jet. | G20: DOC13, SFX18, MUS07
A21: S20 | B21: 5:35 | C21: CHAPTER 3: Canberra's Choices | D21: Ara | E21: historic, connecting the dots | F21: Then, a choice everyone noticed. · In August twenty twenty-five, the Prime Minister announced Australia would recognise the State of Palestine. He called a two-state solution, quote, humanity's best hope to break the cycle of violence. · And he reminded the country that Australia had been the first to back the U.N. plan, back in nineteen forty-seven. | G21: QT06, PH07, DOC02, MG01, SFX24, SFX20, SFX06, MUS07
A22: S21 | B22: 5:59 | C22: CHAPTER 3: Canberra's Choices | D22: Atlas | E22: neutral, attacked from both sides | F22: It was made official at the United Nations in September, with conditions. No role for Hamas, demilitarisation, and Palestinian elections. · And it was attacked from both directions. The Coalition, Israel's government and many Jewish groups said it rewarded Hamas. · A pro-Palestinian advocacy group called it, quote, completely meaningless, while Australia still traded with Israel. | G22: FT04, MAP08, DOC09, QT07, SFX05, SFX11, SFX21, MUS07
A23: S22 | B23: 6:22 | C23: CHAPTER 3: Canberra's Choices | D23: Ara | E23: tense, reading plainly | F23: Then it turned personal. · Israel's prime minister posted that history would remember Albanese as, quote, a weak politician who betrayed Israel and abandoned Australia's Jews. · Albanese replied, quote, I don't take these things personally. | G23: PH10, PH07, QT08, QT09, MG01, MG02, SFX24, SFX05, SFX17, MUS07
A24: S23 | B24: 6:38 | C24: CHAPTER 3: Canberra's Choices | D24: Atlas | E24: weighty, then a turn inward | F24: Visas were cancelled on both sides. Relations between two old friends sank to their lowest point in decades. · Abroad, Canberra was making choices. · But for some Australian families, the war had already come much closer. | G24: MAP01, ST13, SFX19, SFX11, MUS06
A25: S24 | B25: 6:53 | C25: CHAPTER 4: Australian Lives | D25: Ara | E25: tender, slow | F25: Zomi Frankcom grew up in Melbourne. She spent years feeding people in disaster zones. · On the first of April, twenty twenty-four, she and six colleagues from World Central Kitchen were killed, when Israeli drone strikes hit their clearly marked convoy in Gaza. | G25: PH15, ST13, MAP07, MG01, MG02, MUS06
... A28: S27 | B28: 7:48 | C28: CHAPTER 4: Australian Lives | D28: Atlas | E28: empathetic, then even | F28: Australians were also among those killed or affected in Israel. And Australian-Palestinians lost parents, siblings and cousins in Gaza. · Australia granted thousands of visitor visas to people fleeing Gaza. Supporters called it basic humanity. The opposition said vetting was rushed. The government said every applicant was checked. | G28: PH18, PH19, AI05, ST09, SFX19, SFX06, MUS06
A29: S28 | B29: 8:07 | C29: CHAPTER 4: Australian Lives | D29: Ara | E29: quietly ominous | F29: For these families, the war was never far away. · And at home, it was pulling the country in two. | G29: MAP01, MG01, SFX21, SFX24, MUS09 | H29: YES
A30: S29 | B30: 8:15 | C30: CHAPTER 5: A Country Under Strain | D30: Atlas | E30: grave, steady | F30: It began on the seventh of October, twenty twenty-three. · Hamas-led fighters crossed from Gaza into southern Israel. Around twelve hundred people were killed, most of them civilians, and around two hundred and fifty were taken hostage. | G30: MAP07, PH18, MG01, SFX04, MUS09
A31: S30 | B31: 8:34 | C31: CHAPTER 5: A Country Under Strain | D31: Ara | E31: heavy, careful, then precise and attributed | F31: It was the deadliest day for Jewish people since the Holocaust. · Israel's military campaign in Gaza lasted two years. · Gaza's Health Ministry, run by Hamas, reported tens of thousands of Palestinians killed. U.N. agencies broadly treated those figures as reliable, and Israel disputed them. · U.N.-backed experts declared famine in parts of the territory. | G31: PH19, DOC12, DOC11, SFX05, SFX04, SFX18, MUS09
A32: S31 | B32: 9:00 | C32: CHAPTER 5: A Country Under Strain | D32: Atlas | E32: tense, fair | F32: Back home, two days after October the seventh, the Opera House sails were lit in Israel's colours. That night, a pro-Palestinian rally gathered below. · Flares were lit, and antisemitic chanting caused national outrage, though a later police review disputed exactly what was said. | G32: PH16, ST04, DOC17, MG01, SFX24, SFX08, SFX18, MUS09
A33: S32 | B33: 9:18 | C33: CHAPTER 5: A Country Under Strain | D33: Ara | E33: even, two matched cases | F33: The fight moved onto phones and into courtrooms. · The private details of hundreds of Jewish writers and artists were published online, and Parliament made malicious doxxing a crime. · An ABC presenter was taken off air after sharing a human rights report on Gaza, and the Federal Court later found she'd been unlawfully sacked. · Two cases. Opposite sides. | G33: AI09, DOC08, AI12, DOC07, SFX17, SFX19, SFX15, SFX05, MUS09
A34: S33 | B34: 9:43 | C34: CHAPTER 5: A Country Under Strain | D34: Atlas | E34: a divided country | F34: Tens of thousands marched across the Harbour Bridge in the rain. · Jewish groups recorded record numbers of antisemitic incidents. Muslim Australians, especially women wearing the hijab, reported record abuse. · The government appointed two special envoys, one to combat antisemitism, and one to combat Islamophobia. | G34: PH17, ST15, SFX23, DOC14, DOC15, ST20, ST21, DOC18, MG01, SFX24, SFX05, SFX06, SFX18, MUS09
A35: S34 | B35: 10:02 | C35: CHAPTER 5: A Country Under Strain | D35: Ara | E35: realisation, the big payoff | F35: Now look back. · The fires. The jet parts. The expelled ambassador. The recognition. The court cases. The visas. · All of it, in the two years before Bondi. | G35: ST16, AI04, QT01, DOC02, DOC07, ST09, MAP01, MG01, SFX24, SFX14, SFX11, MUS09
A36: S35 | B36: 10:22 | C36: CHAPTER 5: A Country Under Strain | D36: Atlas | E36: hopeful for a beat, then two slow words | F36: In October twenty twenty-five, a U.S.-brokered ceasefire brought the surviving hostages home. · Many hoped the worst was over. · Sixty-five days later, · it wasn't. | G36: DOC20, MAP01, MG01, SFX18, SFX24, MUS09
A37: S36 | B37: 10:35 | C37: CHAPTER 6: Bondi | D37: Ara | E37: quiet dread | F37: Remember the fire, fourteen months earlier, in the same suburb? · Hanukkah is the festival of lights. · On its first night, around a thousand people gathered by the beach to celebrate. | G37: ST01, ST16, ST13, MG01, SFX13, MUS10
A38: S37 | B38: 10:50 | C38: CHAPTER 6: Bondi | D38: Atlas | E38: grief, restrained | F38: Two gunmen, a father and son, opened fire. Police shot the father dead. His son was arrested. · Fifteen people were killed. Among them, a ten-year-old girl, a retired police officer, a rabbi, and a Holocaust survivor. | G38: MAP10, PH22, MUS10
A39: S38 | B39: 11:08 | C39: CHAPTER 6: Bondi | D39: Ara | E39: solemn, plain | F39: That night, the Prime Minister said, quote, · an attack on Jewish Australians is an attack on every Australian. | G39: QT10, PH22, MUS10
A40: S39 | B40: 11:18 | C40: CHAPTER 6: Bondi | D40: Atlas | E40: quiet courage, building | F40: And in the middle of the horror, one man crouched behind a parked car, waited, and ran at one of the gunmen. · He wrestled the gun away. · He was shot and wounded. | G40: AI10, MUS10
A41: S40 | B41: 11:32 | C41: CHAPTER 6: Bondi | D41: Ara | E41: warm, a lump in the throat | F41: His name is Ahmed al Ahmed. · A Syrian-born Muslim. A father of two, who runs a fruit shop. · The attack was aimed at Jewish Australians. · And one of the people who stood in its way was a Muslim Australian. | G41: PH27, ST19, ST13, MG02, MUS10
... A47: S46 | B47: 13:41 | C47: CLOSING | D47: Ara | E47: gentle, caring | F47: Is this Australia's issue? Tell us what you think. · And if any of this has been hard to watch, you're not alone. Support details are in the description. | G47: MUS12, SFX06

Sheet Real Footage
A1: ID | B1: Asset | C1: File name | D1: Used in segments | E1: Starts at (approx) | F1: Free source | G1: Search terms / AI prompt | H1: Licence & credit rule | I1: Key | J1: FREE SWAP fallback | K1: Cost ($) | L1: Status | M1: Credit line (copy from source) | N1: Notes
A2: FT01 | B2: F-35 take-off and flight | C2: FT01_f35_takeoff.mp4 | D2: S18 | E2: 4:57 | F2: DVIDS (dvidshub.net) | G2: F-35A takeoff; F-35 flyby; RAAF F-35 | H2: US Government work, public domain. Credit: DVIDS | I2: 🟢 | J2: PH25 with PAN | K2: 0 | L2: Not started
A3: FT02 | B3: Light Horse in Palestine, 1917 | C3: FT02_light_horse_1917.mp4 | D3: S14 | E3: 3:43 | F3: Australian War Memorial collection (awm.gov.au/collection) — film | G3: light horse palestine 1917 film | H3: Pre-1955 AWM film is public domain. Credit: AWM + item ID | I3: 🟢 | J3: PH02 with PAN + AI03 | K3: 0 | L3: Not started
A4: FT04 | B4: UN General Assembly, September 2025 (recognition) | C4: FT04_unga_sep2025.mp4 | D4: S21 | E4: 5:59 | F4: UN Web TV (webtv.un.org) | G4: two-state solution conference September 2025 general assembly | H4: Free with credit 'UN Web TV'. Confirm UN terms for online channels before publish | I4: 🟡 | J4: MAP08 recognition map + DOC09 card | K4: 0 | L4: Not started
A5: FT05 | B5: UN General Assembly, 1947 | C5: FT05_unga_1947.mp4 | D5: S13 | E5: 3:21 | F5: UN Audiovisual Library (un.org/av) — search archive | G5: general assembly 1947 partition vote | H5: Free with credit if UN terms allow online use; confirm | I5: 🟡 | J5: PH26 + DOC01/DOC02 with ZOOM + MAP03 | K5: 0 | L5: Not started
A6: FT06 | B6: Parliament condolence motion after Bondi (if available) | C6: FT06_bondi_condolence.mp4 | D6: S42 | E6: 12:13 | F6: ParlView | G6: condolence motion Bondi February 2026 | H6: Parliament's conditions. Credit: Parliament of Australia | I6: 🟢 | J6: PH22 memorial photo + DOC04 | K6: 0 | L6: Not started
A7: FT07 | B7: Sussan Ley in the House, 26 Aug 2025 ('neighbour against neighbour') | C7: FT07_ley_house_26aug2025.mp4 | D7: S11 | E7: 2:47 | F7: ParlView (aph.gov.au) | G7: House of Representatives 26 August 2025 Iran statement Ley | H7: Free under Parliament's broadcast conditions; credit Parliament of Australia | I7: 🟢 | J7: QT02 card + PH29 | K7: 0 | L7: Not started

Sheet Photos
A1: ID | B1: Asset | C1: File name | D1: Used in segments | E1: Starts at (approx) | F1: Free source | G1: Search terms / AI prompt | H1: Licence & credit rule | I1: Key | J1: FREE SWAP fallback | K1: Cost ($) | L1: Status | M1: Credit line (copy from source) | N1: Notes
A2: PH02 | B2: Light Horse at Beersheba | C2: PH02_beersheba_light_horse.jpg | D2: S14 | E2: 3:43 | F2: Australian War Memorial collection | G2: beersheba 1917 light horse | H2: Public domain. Credit: AWM + ID | I2: 🟢 | J2: AI03 | K2: 0 | L2: Not started
A3: PH03 | B3: Israeli independence celebrations, 1948 | C3: PH03_israel_1948_celebration.jpg | D3: S15, S45 | E3: 3:58, 13:14 | F3: Israel GPO National Photo Collection / Wikimedia Commons (commons.wikimedia.org) | G3: 1948 independence celebration Tel Aviv | H3: Free with credit 'GPO' (check file page) | I3: 🟢 | J3: MAP03 + kinetic text | K3: 0 | L3: Not started
A4: PH04 | B4: Palestinian refugees, 1948 | C4: PH04_palestinian_refugees_1948.jpg | D4: S15, S45 | E4: 3:58, 13:14 | F4: Wikimedia Commons (commons.wikimedia.org) | G4: Palestinian refugees 1948 | H4: Public domain files exist on Commons — confirm per file | I4: 🟢 | J4: MAP03 + kinetic text | K4: 0 | L4: Not started
A5: PH05 | B5: Post-war migrants at Station Pier, Melbourne | C5: PH05_station_pier_migrants.jpg | D5: S16, S45 | E5: 4:22, 13:14 | F5: National Archives of Australia (PhotoSearch) / Wikimedia Commons (commons.wikimedia.org) | G5: Station Pier migrants 1950 | H5: NAA: copyright expired items free; credit NAA + barcode | I5: 🟢 | J5: AI05 | K5: 0 | L5: Not started
A6: PH06 | B6: 1970s Lebanese/Arab migrant families arriving | C6: PH06_1970s_arrivals.jpg | D6: S16 | E6: 4:22 | F6: National Archives of Australia (PhotoSearch) | G6: Lebanese migrants 1976 arrival Sydney | H6: Check copyright status per item; credit NAA | I6: 🟢 | J6: AI05 | K6: 0 | L6: Not started
A7: PH07 | B7: Anthony Albanese portrait | C7: PH07_albanese.jpg | D7: S10, S20, S22 | E7: 2:25, 5:35, 6:22 | F7: Wikimedia Commons (commons.wikimedia.org) | G7: Anthony Albanese official portrait | H7: Licence on file page (often CC BY / PD). Credit as listed | I7: 🟢 | J7: Name card | K7: 0 | L7: Not started
A8: PH09 | B8: Isaac Herzog portrait | C8: PH09_herzog.jpg | D8: S42 | E8: 12:13 | F8: Wikimedia Commons (commons.wikimedia.org) (GPO uploads) | G8: Isaac Herzog official | H8: As file page | I8: 🟢 | J8: Name card | K8: 0 | L8: Not started
A9: PH10 | B9: Benjamin Netanyahu portrait | C9: PH10_netanyahu.jpg | D9: S22 | E9: 6:22 | F9: Wikimedia Commons (commons.wikimedia.org) (GPO uploads) | G9: Benjamin Netanyahu official | H9: As file page | I9: 🟢 | J9: Name card | K9: 0 | L9: Not started
A10: PH13 | B10: Virginia Bell portrait | C10: PH13_virginia_bell.jpg | D10: S42 | E10: 12:13 | F10: Wikimedia Commons (commons.wikimedia.org) | G10: Virginia Bell judge | H10: As file page; if none use fallback | I10: 🟢 | J10: Name card + DOC04 | K10: 0 | L10: Not started
A11: PH15 | B11: Zomi Frankcom portrait | C11: PH15_zomi_frankcom.jpg | D11: S24, S45 | E11: 6:53, 13:14 | F11: Only with written family permission (contact via World Central Kitchen media) | G11: — | H11: Permission email saved before use | I11: 🟡 | J11: Name card on paper + soft candle light (ST13) — no AI likeness | K11: 0 | L11: Not started
A12: PH16 | B12: Opera House lit blue and white, 9 Oct 2023 | C12: PH16_opera_house_oct2023.jpg | D12: S02, S31 | E12: 0:19, 9:00 | F12: Wikimedia Commons (commons.wikimedia.org) | G12: Sydney Opera House October 2023 Israel lit | H12: CC licence on file page; credit | I12: 🟢 | J12: ST04 night + kinetic text | K12: 0 | L12: Not started
A13: PH17 | B13: Harbour Bridge march, Aug 2025 | C13: PH17_harbour_bridge_march.jpg | D13: S02, S33 | E13: 0:19, 9:43 | F13: Wikimedia Commons (commons.wikimedia.org) | G13: March for Humanity Sydney Harbour Bridge 2025 | H13: CC licence on file page; blur faces | I13: 🟢 | J13: ST15 rain crowd + MAP route line | K13: 0 | L13: Not started
... A22: PH29 | B22: Sussan Ley portrait | C22: PH29_ley.jpg | D22: S11 | E22: 2:47 | F22: Wikimedia Commons (commons.wikimedia.org) / aph.gov.au | G22: Sussan Ley | H22: As file page | I22: 🟢 | J22: Name card | K22: 0 | L22: Not started

Sheet Free Stock
A1: ID | B1: Asset | C1: File name | D1: Used in segments | E1: Starts at (approx) | F1: Free source | G1: Search terms / AI prompt | H1: Licence & credit rule | I1: Key | J1: FREE SWAP fallback | K1: Cost ($) | L1: Status | M1: Credit line (copy from source) | N1: Notes
A2: ST01 | B2: Bondi Beach aerial at dusk | C2: ST01_bondi_dusk_aerial.mp4 | D2: S06, S36 | E2: 1:21, 10:35 | F2: Pexels / Pixabay / Mixkit (free stock) | G2: bondi beach aerial sunset; sydney beach drone dusk | H2: Free licence; no credit needed (credit anyway) | I2: FREE SWAP | J2: Any Sydney beach dusk aerial | K2: 0 | L2: Not started
A3: ST02 | B3: Bondi Beach aerial at dawn | C3: ST02_bondi_dawn_aerial.mp4 | D3: S01, S43 | E3: 0:00, 12:38 | F3: Pexels / Pixabay / Mixkit (free stock) | G3: bondi beach morning aerial; sydney sunrise beach drone | H3: Free licence | I3: FREE SWAP | J3: Any Sydney beach sunrise aerial | K3: 0 | L3: Not started
A4: ST03 | B4: Quiet Sydney street at night | C4: ST03_sydney_street_night.mp4 | D4: S04, S17 | E4: 0:50, 4:43 | F4: Pexels / Pixabay / Mixkit (free stock) | G4: sydney street night; empty street night rain | H4: Free licence | I4: FREE SWAP | J4: Any wet city street at night | K4: 0 | L4: Not started
A5: ST04 | B5: Sydney Opera House, night | C5: ST04_opera_house_night.mp4 | D5: S31 | E5: 9:00 | F5: Pexels / Pixabay / Mixkit (free stock) | G5: sydney opera house night | H5: Free licence | I5: FREE SWAP | J5: Opera House day | K5: 0 | L5: Not started
A6: ST05 | B6: Parliament House, Canberra | C6: ST05_parliament_house.mp4 | D6: S02 | E6: 0:19 | F6: Pexels / Pixabay / Mixkit (free stock) | G6: parliament house canberra | H6: Free licence | I6: FREE SWAP | J6: AI07 generic building — no | K6: 0 | L6: Not started
A7: ST06 | B7: Desert dunes with wind | C7: ST06_desert_wind.mp4 | D7: S14 | E7: 3:43 | F7: Pexels / Pixabay / Mixkit (free stock) | G7: desert sand wind dunes | H7: Free licence | I7: FREE SWAP | J7: AI03 | K7: 0 | L7: Not started
A8: ST07 | B8: CNC machining with sparks | C8: ST07_cnc_sparks.mp4 | D8: S18 | E8: 4:57 | F8: Pexels / Pixabay / Mixkit (free stock) | G8: cnc machine sparks; metal machining | H8: Free licence | I8: FREE SWAP | J8: AI04 | K8: 0 | L8: Not started
A9: ST09 | B9: Airport arrivals, families embracing | C9: ST09_airport_hug.mp4 | D9: S02, S27, S34 | E9: 0:19, 7:48, 10:02 | F9: Pexels / Pixabay / Mixkit (free stock) | G9: airport arrivals hug family | H9: Free licence | I9: FREE SWAP | J9: AI05 | K9: 0 | L9: Not started
A10: ST12 | B10: Courthouse exterior | C10: ST12_courthouse.mp4 | D10: S02 | E10: 0:19 | F10: Pexels / Pixabay / Mixkit (free stock) | G10: courthouse exterior columns | H10: Free licence | I10: FREE SWAP | J10: DOC07 ZOOM | K10: 0 | L10: Not started
A11: ST13 | B11: Candles and flowers at night | C11: ST13_candles_flowers.mp4 | D11: S02, S23, S24, S25, S36, S40, S44 | E11: 0:19, 6:38, 6:53, 7:16, 10:35, 11:32 … | F11: Pexels / Pixabay / Mixkit (free stock) | G11: memorial candles flowers night | H11: Free licence | I11: FREE SWAP | J11: Single candle on black | K11: 0 | L11: Not started
A12: ST15 | B12: Crowd with umbrellas in rain | C12: ST15_rain_crowd.mp4 | D12: S33 | E12: 9:43 | F12: Pexels / Pixabay / Mixkit (free stock) | G12: crowd rain umbrellas city | H12: Free licence; no readable placards | I12: FREE SWAP | J12: PH17 | K12: 0 | L12: Not started
A13: ST16 | B13: Flames close-up on black | C13: ST16_flames_black.mp4 | D13: S03, S12, S34, S36 | E13: 0:38, 3:05, 10:02, 10:35 | F13: Pexels / Pixabay / Mixkit (free stock) | G13: fire flames black background | H13: Free licence | I13: FREE SWAP | J13: AI01 | K13: 0 | L13: Not started
... A17: ST21 | B17: Mosque exterior (respectful, generic) | C17: ST21_mosque_exterior.mp4 | D17: S33 | E17: 9:43 | F17: Pexels / Pixabay (free stock) | G17: mosque exterior | H17: Free licence; same framing and duration as ST20 | I17: FREE SWAP | J17: Chart only | K17: 0 | L17: Not started

Sheet AI B-roll
A1: ID | B1: Asset | C1: File name | D1: Used in segments | E1: Starts at (approx) | F1: Free source | G1: Search terms / AI prompt | H1: Licence & credit rule | I1: Key | J1: FREE SWAP fallback | K1: Cost ($) | L1: Status | M1: Credit line (copy from source) | N1: Notes
A2: AI01 | B2: Restaurant shopfront at night, glow inside | C2: AI01_restaurant_glow.mp4 | D2: S04 | E2: 0:50 | F2: Grok Imagine (your Grok account). Backup free tiers: Kling, Hailuo, Pika | G2: Small suburban restaurant shopfront on a quiet Australian beachside street at night, warm orange glow slowly growing behind the window, wet asphalt reflecting a streetlight, no people, no readable signage, slow push-in | H2: Your Grok account terms. Label 'Dramatised reconstruction' on screen | I2: FREE SWAP | J2: ST16 flames | K2: 0 | L2: Not started
A3: AI02 | B3: Hands passing a cash envelope | C3: AI02_envelope_hands.mp4 | D3: S05 | E3: 1:08 | F3: Grok Imagine (your Grok account). Backup free tiers: Kling, Hailuo, Pika | G3: Close-up of two anonymous hands exchanging a thick paper envelope under a harsh streetlight at night, faces out of frame, noir mood, slow motion | H3: Symbolic; label 'Dramatised reconstruction' | I3: FREE SWAP | J3: Kinetic text only | K3: 0 | L3: Not started
A4: AI03 | B4: Cavalry silhouettes at sunset | C4: AI03_cavalry_silhouettes.mp4 | D4: S14 | E4: 3:43 | F4: Grok Imagine (your Grok account). Backup free tiers: Kling, Hailuo, Pika | G4: Silhouettes of First World War cavalry riders galloping across desert dunes at sunset, backlit dust clouds, wide shot, warm sepia grade, no faces visible | H4: Label 'Dramatised reconstruction' | I4: FREE SWAP | J4: PH02 PAN | K4: 0 | L4: Not started
A5: AI04 | B5: Machined metal part rotating on black | C5: AI04_metal_part.mp4 | D5: S18, S34 | E5: 4:57, 10:02 | F5: Grok Imagine (your Grok account). Backup free tiers: Kling, Hailuo, Pika | G5: A precision-machined aluminium aerospace component slowly rotating on a pure black background, rim lighting, macro detail, product-shot style, seamless loop (generic part) | H5: Symbolic | I5: FREE SWAP | J5: ST07 | K5: 0 | L5: Not started
A6: AI05 | B6: Two suitcases on a ship deck at dawn | C6: AI05_suitcases_ship.mp4 | D6: S16, S27 | E6: 4:22, 7:48 | F6: Grok Imagine (your Grok account). Backup free tiers: Kling, Hailuo, Pika | G6: Two worn vintage leather suitcases on the wooden deck of an old passenger ship at dawn, sea mist, warm light, slow dolly, 1950s film look | H6: Symbolic | I6: FREE SWAP | J6: PH05 PAN | K6: 0 | L6: Not started
A7: AI07 | B7: Heavy diplomatic door closing | C7: AI07_door_closing.mp4 | D7: S11 | E7: 2:47 | F7: Grok Imagine (your Grok account). Backup free tiers: Kling, Hailuo, Pika | G7: Heavy ornate wooden door of a stately building slowly closing, brass handle, dramatic side light, no flags, no symbols | H7: Symbolic | I7: FREE SWAP | J7: Kinetic text + SFX door | K7: 0 | L7: Not started
A8: AI09 | B8: Phones lighting up in the dark | C8: AI09_phones_notifications.mp4 | D8: S32 | E8: 9:18 | F8: Grok Imagine (your Grok account). Backup free tiers: Kling, Hailuo, Pika | G8: Several smartphones lying on a dark table, screens lighting up one after another with blurred unreadable notifications, cold blue light | H8: Symbolic | I8: FREE SWAP | J8: ST11 | K8: 0 | L8: Not started
A9: AI10 | B9: One hand steadying another | C9: AI10_hand_steadying.mp4 | D9: S39 | E9: 11:18 | F9: Grok Imagine (your Grok account). Backup free tiers: Kling, Hailuo, Pika | G9: Close-up of one hand reaching out to firmly steady another hand, soft dusk light, shallow depth of field, no faces, calm, slow motion | H9: Symbolic; must stay abstract — no depiction of the attack | I9: FREE SWAP | J9: ST13 candle | K9: 0 | L9: Not started
A10: AI11 | B10: Hands of different ages holding | C10: AI11_hands_together.mp4 | D10: S45 | E10: 13:14 | F10: Grok Imagine (your Grok account). Backup free tiers: Kling, Hailuo, Pika | G10: Close-up of several hands of different ages gently holding each other, warm morning light, soft-focus ocean behind, hopeful, slow motion | H10: Symbolic | I10: FREE SWAP | J10: ST17 waves | K10: 0 | L10: Not started
A11: AI12 | B11: Empty radio/news desk at night | C11: AI12_news_desk.mp4 | D11: S32 | E11: 9:18 | F11: Grok Imagine (your Grok account). Backup free tiers: Kling, Hailuo, Pika | G11: Empty broadcast studio at night, a single microphone under a spotlight, monitors glowing with blurred unreadable text, slow push-in | H11: Symbolic | I11: FREE SWAP | J11: ST11 | K11: 0 | L11: Not started

Sheet Quote Cards
A1: ID | B1: Asset | C1: File name | D1: Used in segments | E1: Starts at (approx) | F1: Free source | G1: Search terms / AI prompt | H1: Licence & credit rule | I1: Key | J1: FREE SWAP fallback | K1: Cost ($) | L1: Status | M1: Credit line (copy from source) | N1: Notes
A2: QT01 | B2: Albanese: "extraordinary and dangerous acts of aggression orchestrated by a foreign nation on Australian soil" (26 Aug 2025) | C2: QT01_albanese_iran.png | D2: S10, S34 | E2: 2:25, 10:02 | F2: Built by the pipeline as a quote card (no download). Open the primary source to confirm exact wording | G2: pm.gov.au transcript, 26 Aug 2025 | H2: Short quote, attributed, news reporting | I2: 🟢 | J2: — | K2: 0 | L2: Not started
A3: QT02 | B3: Sussan Ley: "turn neighbour against neighbour and Australian against Australian" (26 Aug 2025) | C3: QT02_ley_neighbour.png | D3: S11, S44 | E3: 2:47, 12:57 | F3: Built by the pipeline as a quote card (no download). Open the primary source to confirm exact wording | G3: Hansard, House of Representatives, 26 Aug 2025 | H3: Short quote, attributed | I3: 🟢 | J3: — | K3: 0 | L3: Not started
A4: QT03 | B4: Albanese on Zomi Frankcom: "completely unacceptable" (Apr 2024) | C4: QT03_albanese_frankcom.png | D4: S25 | E4: 7:16 | F4: Built by the pipeline as a quote card (no download). Open the primary source to confirm exact wording | G4: PM Transcripts (pmtranscripts.pmc.gov.au), April 2024 | H4: Short quote, attributed | I4: 🟢 | J4: — | K4: 0 | L4: Not started
A5: QT04 | B5: Netanyahu: forces "unintentionally harmed non-combatants" (2 Apr 2024) | C5: QT04_netanyahu_wck.png | D5: S25 | E5: 7:16 | F5: Built by the pipeline as a quote card (no download). Open the primary source to confirm exact wording | G5: Israeli PM's video statement, 2 Apr 2024 | H5: Short quote, attributed | I5: 🟢 | J5: — | K5: 0 | L5: Not started
A6: QT05 | B6: Frankcom family: "a legacy of compassion, bravery and love" (Apr 2024) | C6: QT05_family.png | D6: S25 | E6: 7:16 | F6: Built by the pipeline as a quote card (no download). Open the primary source to confirm exact wording | G6: Family statement, April 2024 | H6: Short quote, attributed | I6: 🟢 | J6: — | K6: 0 | L6: Not started
A7: QT06 | B7: Albanese: "humanity's best hope to break the cycle of violence" (11 Aug 2025) | C7: QT06_albanese_recognition.png | D7: S20 | E7: 5:35 | F7: Built by the pipeline as a quote card (no download). Open the primary source to confirm exact wording | G7: pm.gov.au transcript, 11 Aug 2025 | H7: Short quote, attributed | I7: 🟢 | J7: — | K7: 0 | L7: Not started
A8: QT07 | B8: Nasser Mashni (APAN): recognition "completely meaningless" while trade continues (11 Aug 2025) | C8: QT07_mashni.png | D8: S21 | E8: 5:59 | F8: Built by the pipeline as a quote card (no download). Open the primary source to confirm exact wording | G8: APAN statement / AP report, 11 Aug 2025 | H8: Short quote, attributed | I8: 🟢 | J8: — | K8: 0 | L8: Not started
A9: QT08 | B9: Netanyahu post: "a weak politician who betrayed Israel and abandoned Australia's Jews" (19 Aug 2025) | C9: QT08_netanyahu_post.png | D9: S22 | E9: 6:22 | F9: Built by the pipeline as a quote card (no download). Open the primary source to confirm exact wording — show as a labelled recreation, never a screenshot | G9: Official Israeli PM X account, 19 Aug 2025 | H9: Short quote, attributed | I9: 🟢 | J9: — | K9: 0 | L9: Not started
A10: QT09 | B10: Albanese: "I don't take these things personally" (20 Aug 2025) | C10: QT09_albanese_reply.png | D10: S22 | E10: 6:22 | F10: Built by the pipeline as a quote card (no download). Open the primary source to confirm exact wording | G10: Press conference, 20 Aug 2025 (pm.gov.au transcript) | H10: Short quote, attributed | I10: 🟢 | J10: — | K10: 0 | L10: Not started
A11: QT10 | B11: Albanese: "An attack on Jewish Australians is an attack on every Australian" (14 Dec 2025) | C11: QT10_albanese_bondi.png | D11: S38 | E11: 11:08 | F11: Built by the pipeline as a quote card (no download). Open the primary source to confirm exact wording | G11: pm.gov.au transcript, 14 Dec 2025 | H11: Short quote, attributed | I11: 🟢 | J11: — | K11: 0 | L11: Not started
A12: QT11 | B12: Albanese on Ahmed al Ahmed: "an inspiration for all Australians" (Dec 2025) | C12: QT11_albanese_ahmed.png | D12: S41 | E12: 11:52 | F12: Built by the pipeline as a quote card (no download). Open the primary source to confirm exact wording | G12: pm.gov.au transcript, Dec 2025 | H12: Short quote, attributed | I12: 🟢 | J12: — | K12: 0 | L12: Not started
A13: QT12 | B13: Mike Burgess (ASIO): "layer cake" of middlemen (26 Aug 2025) | C13: QT12_burgess.png | D13: S08 | E13: 1:54 | F13: Built by the pipeline as a quote card (no download). Open the primary source to confirm exact wording | G13: ASIO / press conference transcript, 26 Aug 2025 | H13: Short quote, attributed | I13: 🟢 | J13: — | K13: 0 | L13: Not started

Sheet Evidence Cards
A1: ID | B1: Asset | C1: File name | D1: Used in segments | E1: Starts at (approx) | F1: Free source | G1: Search terms / AI prompt | H1: Licence & credit rule | I1: Key | J1: FREE SWAP fallback | K1: Cost ($) | L1: Status | M1: Credit line (copy from source) | N1: Notes
A2: DOC01 | B2: UN Resolution 181 (II), 29 Nov 1947 | C2: DOC01_res181.png | D2: S13 | E2: 3:21 | F2: UN Digital Library (digitallibrary.un.org) | G2: A/RES/181(II) | H2: UN documents free to reproduce with citation | I2: 🟢 | J2: — | K2: 0 | L2: Not started
A3: DOC02 | B3: UNGA voting record, 29 Nov 1947 | C3: DOC02_vote_record.png | D3: S02, S13, S14, S20, S34 | E3: 0:19, 3:21, 3:43, 5:35, 10:02 | F3: UN Digital Library — 128th plenary meeting records | G3: UNGA 128th plenary meeting 29 November 1947 | H3: Free with citation. Confirm Australia's place in the roll call | I3: 🟢 | J3: — | K3: 0 | L3: Not started
A4: DOC03 | B4: PM statement: ASIO assessment on Iran, Aug 2025 | C4: DOC03_pm_iran_statement.png | D4: S10 | E4: 2:25 | F4: pm.gov.au (media release / transcript) | G4: Albanese Iran ASIO statement August 2025 | H4: Commonwealth material; cite | I4: 🟢 | J4: — | K4: 0 | L4: Not started
A5: DOC04 | B5: Royal Commission on Antisemitism and Social Cohesion — establishment, Jan 2026 | C5: DOC04_rc_established.png | D5: S42 | E5: 12:13 | F5: asc.royalcommission.gov.au / pm.gov.au | G5: royal commission antisemitism social cohesion letters patent | H5: Cite | I5: 🟢 | J5: — | K5: 0 | L5: Not started
A6: DOC05 | B6: Royal Commission interim report, Apr 2026 | C6: DOC05_rc_interim.png | D6: S42 | E6: 12:13 | F6: asc.royalcommission.gov.au | G6: interim report 30 April 2026 | H6: Cite | I6: 🟢 | J6: — | K6: 0 | L6: Not started
A7: DOC06 | B7: Binskin report on the WCK strike | C7: DOC06_binskin.png | D7: S26 | E7: 7:30 | F7: dfat.gov.au | G7: Special Adviser Binskin report World Central Kitchen | H7: Cite; copy the exact finding wording | I7: 🟢 | J7: — | K7: 0 | L7: Not started
A8: DOC07 | B8: Federal Court: Lattouf v ABC (2025) | C8: DOC07_lattouf_judgment.png | D8: S32, S34 | E8: 9:18, 10:02 | F8: Federal Court of Australia judgments / AustLII | G8: Lattouf v Australian Broadcasting Corporation 2025 FCA | H8: Judgments free to reproduce | I8: 🟢 | J8: — | K8: 0 | L8: Not started
A9: DOC08 | B9: Doxxing offence legislation (2024) | C9: DOC08_doxxing_law.png | D9: S32 | E9: 9:18 | F9: legislation.gov.au | G9: Privacy and Other Legislation Amendment Act 2024 doxxing | H9: Cite; confirm Act name | I9: 🟢 | J9: — | K9: 0 | L9: Not started
A10: DOC09 | B10: Australia recognises the State of Palestine, Sept 2025 | C10: DOC09_recognition_statement.png | D10: S21 | E10: 5:59 | F10: pm.gov.au / foreignminister.gov.au | G10: recognition State of Palestine statement September 2025 | H10: Cite | I10: 🟢 | J10: — | K10: 0 | L10: Not started
A11: DOC10 | B11: ABS Census — religious affiliation | C11: DOC10_census.png | D11: S16 | E11: 4:22 | F11: abs.gov.au | G11: Census 2021 religious affiliation Judaism Islam | H11: Cite; use latest census | I11: 🟢 | J11: — | K11: 0 | L11: Not started
A12: DOC11 | B12: IPC famine classification, Gaza | C12: DOC11_ipc.png | D12: S30 | E12: 8:34 | F12: ipcinfo.org | G12: IPC Gaza famine August 2025 | H12: Cite with date | I12: 🟢 | J12: — | K12: 0 | L12: Not started
A13: DOC12 | B13: Gaza casualty figures (attributed) | C13: DOC12_gaza_figures.png | D13: S30 | E13: 8:34 | F13: ochaopt.org (reports Health Ministry figures) | G13: OCHA Gaza humanitarian update casualties | H13: Cite with as-of date and attribution | I13: 🟢 | J13: — | K13: 0 | L13: Not started
... A22: DOC21 | B22: 2026: IDF clears personnel over the WCK strike; family response | C22: DOC21_idf_2026.png | D22: S26 | E22: 7:30 | F22: DFAT / PM statement (Aug 2026) and reports of the family statement | G22: IDF cleared Zomi Frankcom 2026 Albanese outrage | H22: Cite; confirm date and wording | I22: 🟢 | J22: — | K22: 0 | L22: Not started

Sheet Maps
A1: ID | B1: Asset | C1: File name | D1: Used in segments | E1: Starts at (approx) | F1: Free source | G1: Search terms / AI prompt | H1: Licence & credit rule | I1: Key | J1: FREE SWAP fallback | K1: Cost ($) | L1: Status | M1: Credit line (copy from source) | N1: Notes
A2: MAP01 | B2: THE THREAD — master globe, Sydney → Gaza 14,000 km | C2: (built) | D2: S03, S07, S12, S17, S23, S28, S34, S35, S41, S42, S43, S44 | E2: 0:38, 1:34, 3:05, 4:43, 6:38, 8:07 … | F2: Built by the animation pipeline (no download); data: Natural Earth (public domain) | G2: Nodes: 1947 VOTE · JET PARTS · THE FIRE · WORDS · LIVES · RECOGNITION · THE SKEPTICS · OCT 7 · BONDI | H2: Natural Earth: public domain | I2: FREE SWAP | J2: — | K2: 0 | L2: Not started
A3: MAP02 | B3: Beersheba 1917 locator + charge arrow | C3: (built) | D3: S14 | E3: 3:43 | F3: Built by the animation pipeline (no download) | G3: Natural Earth + AWM descriptions | H3: Public domain data | I3: FREE SWAP | J3: — | K3: 0 | L3: Not started
A4: MAP03 | B4: 1947 UN partition plan | C4: (built) | D4: S13 | E4: 3:21 | F4: Built by the animation pipeline (no download); reference: UN map of the plan | G4: Neutral sand/slate fills, Jerusalem zone | H4: Cite UN map | I4: FREE SWAP | J4: — | K4: 0 | L4: Not started
A5: MAP04 | B5: Migration flows to Australia | C5: (built) | D5: S16 | E5: 4:22 | F5: Built by the animation pipeline (no download) | G5: Europe→Melbourne; Middle East→Sydney | H5: Own | I5: FREE SWAP | J5: — | K5: 0 | L5: Not started
A6: MAP05 | B6: F-35 global parts pool | C6: (built) | D6: S18 | E6: 4:57 | F6: Built by the animation pipeline (no download) | G6: AU factories → global pool → operators (all same colour) | H6: Own; label 'simplified' | I6: FREE SWAP | J6: — | K6: 0 | L6: Not started
A7: MAP06 | B7: Alleged money trail Tehran → intermediaries → Sydney/Melbourne | C7: (built) | D7: S09 | E7: 2:09 | F7: Built by the animation pipeline (no download) | G7: Dotted line, 'ALLEGED' tag | H7: Own | I7: FREE SWAP | J7: — | K7: 0 | L7: Not started
A8: MAP07 | B8: Gaza Strip and southern Israel | C8: (built) | D8: S24, S29 | E8: 6:53, 8:15 | F8: Built by the animation pipeline (no download); reference: OCHA maps | G8: Border, Gaza City, Deir al-Balah, convoy route | H8: Cite OCHA reference | I8: FREE SWAP | J8: — | K8: 0 | L8: Not started
A9: MAP08 | B9: Recognition map, Sept 2025 | C9: (built) | D9: S21 | E9: 5:59 | F9: Built by the animation pipeline (no download) | G9: Australia, UK, Canada, France light together | H9: Own | I9: FREE SWAP | J9: — | K9: 0 | L9: Not started
A10: MAP10 | B10: Bondi locator (stylised) | C10: (built) | D10: S37 | E10: 10:50 | F10: Built by the animation pipeline (no download); data: OpenStreetMap (credit 'OpenStreetMap contributors') | G10: One soft marker, no attack detail | H10: ODbL attribution | I10: FREE SWAP | J10: — | K10: 0 | L10: Not started
A11: MAP11 | B11: Sydney → Melbourne line (cold open) | C11: (built) | D11: S04 | E11: 0:50 | F11: Built by the animation pipeline (no download) | G11: Two pins, one line | H11: Own | I11: FREE SWAP | J11: — | K11: 0 | L11: Not started
A12: MG01 | B12: BONDI COUNTDOWN ticker (recurring) | C12: (built) | D12: S01, S02, S04, S08, S10, S12, S13, S17, S20, S22, S24, S28, S29, S31, S33, S34, S35, S36, S42 | E12: 0:00, 0:19, 0:50, 1:54, 2:25, 3:05 … | F12: Built by the animation pipeline (no download) | G12: Split-flap: date on top line, 'BONDI −420 DAYS' below; amber digits | H12: Own | I12: FREE SWAP | J12: — | K12: 0 | L12: Not started
A13: MG02 | B13: Cast board (the five people viewers must remember) | C13: (built) | D13: S10, S11, S22, S24, S40 | E13: 2:25, 2:47, 6:22, 6:53, 11:32 | F13: Built by the animation pipeline (no download) | G13: Five name cards: Albanese · Netanyahu · Sussan Ley · Zomi Frankcom · Ahmed al Ahmed (real photos only where free; otherwise name cards) | H13: Own | I13: FREE SWAP | J13: — | K13: 0 | L13: Not started

Sheet Music
A1: ID | B1: Asset | C1: File name | D1: Used in segments | E1: Starts at (approx) | F1: Free source | G1: Search terms / AI prompt | H1: Licence & credit rule | I1: Key | J1: FREE SWAP fallback | K1: Cost ($) | L1: Status | M1: Credit line (copy from source) | N1: Notes
A2: MUS01 | B2: Mystery pulse — cold open | C2: MUS01_mystery_pulse.mp3 | D2: S03, S04, S05, S06 | E2: 0:38, 0:50, 1:08, 1:21 | F2: YouTube Audio Library (studio.youtube.com → Audio Library) or Pixabay Music | G2: dark ambient pulse; suspense ticking underscore | H2: YouTube Audio Library: check 'attribution required' column; Pixabay: free | I2: FREE SWAP | J2: Any low suspense bed | K2: 0 | L2: Not started
A3: MUS02 | B3: Historical strings — Ch 1 | C3: MUS02_history_strings.mp3 | D3: S13, S14, S16 | E3: 3:21, 3:43, 4:22 | F3: YouTube Audio Library (studio.youtube.com → Audio Library) or Pixabay Music | G3: solemn strings documentary; cinematic history | H3: As above | I3: FREE SWAP | J3: — | K3: 0 | L3: Not started
A4: MUS04 | B4: Investigative thriller — Ch 3 | C4: MUS04_investigation.mp3 | D4: S08, S09, S10, S11, S12 | E4: 1:54, 2:09, 2:25, 2:47, 3:05 | F4: YouTube Audio Library (studio.youtube.com → Audio Library) or Pixabay Music | G4: investigation thriller tension; spy suspense | H4: As above | I4: FREE SWAP | J4: — | K4: 0 | L4: Not started
A5: MUS06 | B5: Soft sombre piano — Ch 5 and quiet moments | C5: MUS06_sombre_piano.mp3 | D5: S15, S23, S24, S25, S26, S27 | E5: 3:58, 6:38, 6:53, 7:16, 7:30, 7:48 | F5: YouTube Audio Library (studio.youtube.com → Audio Library) or Pixabay Music | G5: sad piano minimal; emotional piano slow | H5: As above | I5: FREE SWAP | J5: — | K5: 0 | L5: Not started
A6: MUS07 | B6: Serious strings with pulse — Ch 6 | C6: MUS07_diplomatic_strings.mp3 | D6: S17, S18, S19, S20, S21, S22 | E6: 4:43, 4:57, 5:15, 5:35, 5:59, 6:22 | F6: YouTube Audio Library (studio.youtube.com → Audio Library) or Pixabay Music | G6: serious strings pulse; political drama | H6: As above | I6: FREE SWAP | J6: — | K6: 0 | L6: Not started
A7: MUS09 | B7: Heavy drone building — Ch 8 | C7: MUS09_heavy_drone.mp3 | D7: S28, S29, S30, S31, S32, S33, S34, S35 | E7: 8:07, 8:15, 8:34, 9:00, 9:18, 9:43 … | F7: YouTube Audio Library (studio.youtube.com → Audio Library) or Pixabay Music | G7: dark cinematic drone build; low strings tension | H7: As above | I7: FREE SWAP | J7: — | K7: 0 | L7: Not started
A8: MUS10 | B8: Solo cello grief — Ch 9 | C8: MUS10_cello_grief.mp3 | D8: S01, S02, S36, S37, S38, S39, S40, S41, S42 | E8: 0:00, 0:19, 10:35, 10:50, 11:08, 11:18 … | F8: YouTube Audio Library (studio.youtube.com → Audio Library) or Pixabay Music | G8: sad cello solo; grief cello | H8: As above | I8: FREE SWAP | J8: MUS06 | K8: 0 | L8: Not started
A9: MUS11 | B9: Hopeful-unresolved closing | C9: MUS11_closing.mp3 | D9: S42, S43, S44, S45 | E9: 12:13, 12:38, 12:57, 13:14 | F9: YouTube Audio Library (studio.youtube.com → Audio Library) or Pixabay Music | G9: hopeful reflective ending; emotional uplifting soft | H9: As above | I9: FREE SWAP | J9: — | K9: 0 | L9: Not started
A10: MUS12 | B10: Signature motif (title + chapter cards) | C10: MUS12_motif.mp3 | D10: S07, S08, S13, S18, S45, S46 | E10: 1:34, 1:54, 3:21, 4:57, 13:14, 13:41 | F10: YouTube Audio Library (studio.youtube.com → Audio Library) or Pixabay Music | G10: short piano motif documentary intro; cinematic logo piano | H10: As above — pick one 3–5s phrase and reuse it every time | I10: FREE SWAP | J10: — | K10: 0 | L10: Not started

Sheet SFX
A1: ID | B1: Asset | C1: File name | D1: Used in segments | E1: Starts at (approx) | F1: Free source | G1: Search terms / AI prompt | H1: Licence & credit rule | I1: Key | J1: FREE SWAP fallback | K1: Cost ($) | L1: Status | M1: Credit line (copy from source) | N1: Notes
A2: SFX02 | B2: Fire ignition whoosh and crackle | C2: SFX02_fire.mp3 | D2: S03, S04, S12 | E2: 0:38, 0:50, 3:05 | F2: Pixabay Sound Effects / Freesound (CC0 filter) / Mixkit | G2: fire whoosh crackle | H2: As above | I2: FREE SWAP | J2: — | K2: 0 | L2: Not started
A3: SFX03 | B3: Distant siren | C3: SFX03_siren.mp3 | D3: S04 | E3: 0:50 | F3: Pixabay Sound Effects / Freesound (CC0 filter) / Mixkit | G3: distant siren night | H3: As above | I3: FREE SWAP | J3: — | K3: 0 | L3: Not started
A4: SFX04 | B4: Typewriter keys | C4: SFX04_typewriter.mp3 | D4: S29, S30 | E4: 8:15, 8:34 | F4: Pixabay Sound Effects / Freesound (CC0 filter) / Mixkit | G4: typewriter typing | H4: As above | I4: FREE SWAP | J4: — | K4: 0 | L4: Not started
A5: SFX05 | B5: Soft whoosh (map lines, thread) | C5: SFX05_whoosh.mp3 | D5: S02, S03, S04, S07, S09, S13, S16, S17, S18, S21, S22, S30, S32, S33 | E5: 0:19, 0:38, 0:50, 1:34, 2:09, 3:21 … | F5: Pixabay Sound Effects / Freesound (CC0 filter) / Mixkit | G5: soft whoosh swoosh | H5: As above | I5: FREE SWAP | J5: — | K5: 0 | L5: Not started
A6: SFX06 | B6: Digital tick | C6: SFX06_tick.mp3 | D6: S02, S08, S09, S11, S16, S17, S18, S20, S27, S33, S43, S44, S46 | E6: 0:19, 1:54, 2:09, 2:47, 4:22, 4:43 … | F6: Pixabay Sound Effects / Freesound (CC0 filter) / Mixkit | G6: ui tick click digital | H6: As above | I6: FREE SWAP | J6: — | K6: 0 | L6: Not started
A7: SFX07 | B7: Film projector rattle | C7: SFX07_projector.mp3 | D7: S12, S13 | E7: 3:05, 3:21 | F7: Pixabay Sound Effects / Freesound (CC0 filter) / Mixkit | G7: film projector loop | H7: As above | I7: FREE SWAP | J7: — | K7: 0 | L7: Not started
A8: SFX08 | B8: Crowd ambience, distant | C8: SFX08_crowd.mp3 | D8: S31 | E8: 9:00 | F8: Pixabay Sound Effects / Freesound (CC0 filter) / Mixkit | G8: crowd ambience distant protest | H8: As above | I8: FREE SWAP | J8: — | K8: 0 | L8: Not started
A9: SFX09 | B9: Jet flyby | C9: SFX09_jet.mp3 | D9: S18 | E9: 4:57 | F9: Pixabay Sound Effects / Freesound (CC0 filter) / Mixkit | G9: jet flyby | H9: As above | I9: FREE SWAP | J9: — | K9: 0 | L9: Not started
A10: SFX10 | B10: Factory machining | C10: SFX10_machining.mp3 | D10: S18 | E10: 4:57 | F10: Pixabay Sound Effects / Freesound (CC0 filter) / Mixkit | G10: cnc machining factory | H10: As above | I10: FREE SWAP | J10: — | K10: 0 | L10: Not started
A11: SFX11 | B11: Low sub boom (reveals only) | C11: SFX11_boom.mp3 | D11: S04, S07, S10, S21, S23, S34 | E11: 0:50, 1:34, 2:25, 5:59, 6:38, 10:02 | F11: Pixabay Sound Effects / Freesound (CC0 filter) / Mixkit | G11: cinematic boom impact low | H11: As above | I11: FREE SWAP | J11: — | K11: 0 | L11: Not started
A12: SFX13 | B12: Morning waves and gulls | C12: SFX13_waves_gulls.mp3 | D12: S01, S36, S43 | E12: 0:00, 10:35, 12:38 | F12: Pixabay Sound Effects / Freesound (CC0 filter) / Mixkit | G12: ocean waves seagulls morning | H12: As above | I12: FREE SWAP | J12: — | K12: 0 | L12: Not started
A13: SFX14 | B13: Riser | C13: SFX14_riser.mp3 | D13: S03, S34 | E13: 0:38, 10:02 | F13: Pixabay Sound Effects / Freesound (CC0 filter) / Mixkit | G13: cinematic riser | H13: As above | I13: FREE SWAP | J13: — | K13: 0 | L13: Not started
... A23: SFX24 | B23: Countdown tick (low, heartbeat-like single tick) | C23: SFX24_countdown_tick.mp3 | D23: S01, S02, S03, S04, S10, S12, S13, S14, S17, S20, S22, S28, S31, S33, S34, S35, S42 | E23: 0:00, 0:19, 0:38, 0:50, 2:25, 3:05 … | F23: Pixabay Sound Effects / Freesound (CC0 filter) / Mixkit | G23: low clock tick heartbeat; deep single tick | H23: CC0 / Pixabay licence | I23: FREE SWAP | J23: SFX06 pitched down | K23: 0 | L23: Not started

Sheet Voiceover
A1: ID | B1: Asset | C1: File name | D1: Used in segments | E1: Starts at (approx) | F1: Free source | G1: Search terms / AI prompt | H1: Licence & credit rule | I1: Key | J1: FREE SWAP fallback | K1: Cost ($) | L1: Status | M1: Credit line (copy from source) | N1: Notes
A2: S01 | B2: Atlas | C2: S01_ATLAS.mp3 | D2: S01 | E2: 0:00 | F2: Grok TTS (your account) | G2: Bondi Beach. [pause] On the fourteenth of December, twenty twenty-five, the first night of Hanukkah, it became the scene of the deadliest terror attack ever carried out on Australian soil. [pause] Fifteen people were killed. | H2: AI voice — disclose in description | I2: FREE SWAP | J2: — | K2: 0 | L2: Not started | N2: Delivery: quiet, grave, unhurried
A3: S02 | B3: Ara (backup: Eve) | C3: S02_ARA.mp3 | D3: S02 | E3: 0:19 | F3: Grok TTS (your account) | G3: Afterwards, the whole country asked the same question. [pause] How did this happen here? [pause] Police say the gunmen were inspired by Islamic State. But the Australia they struck had been under strain for two years, ever since the war in Gaza began in October twenty twenty-three. | H3: AI voice — disclose in description | I3: FREE SWAP | J3: — | K3: 0 | L3: Not started | N3: Delivery: searching, clear
A4: S03 | B4: Atlas | C4: S03_ATLAS.mp3 | D4: S03 | E4: 0:38 | F4: Grok TTS (your account) | G4: This film follows the threads of that strain. [pause] Some go back seventy-eight years. [pause] One goes back just fourteen months, to a fire [pause] in the same suburb. | H4: AI voice — disclose in description | I4: FREE SWAP | J4: — | K4: 0 | L4: Not started | N4: Delivery: leaning in, conspiratorial
A5: S04 | B5: Ara (backup: Eve) | C5: S04_ARA.mp3 | D5: S04 | E5: 0:50 | F5: Grok TTS (your account) | G5: October, twenty twenty-four. In the early hours, a small kosher restaurant in Bondi goes up in flames. Nobody is hurt. Police treat it as a local crime. [pause] Seven weeks later, eight hundred kilometres south, a synagogue in Melbourne is firebombed before dawn. | H5: AI voice — disclose in description | I5: FREE SWAP | J5: — | K5: 0 | L5: Not started | N5: Delivery: quiet, then a chill
A6: S05 | B6: Atlas | C6: S05_ATLAS.mp3 | D6: S05 | E6: 1:08 | F6: Grok TTS (your account) | G6: What almost nobody knew then was that the people who lit these fires were allegedly <slow>paid.</slow> [pause] And the money trail led to a government on the other side of the world. | H6: AI voice — disclose in description | I6: FREE SWAP | J6: — | K6: 0 | L6: Not started | N6: Delivery: hushed, ominous
A7: S06 | B7: Ara (backup: Eve) | C7: S06_ARA.mp3 | D7: S06 | E7: 1:21 | F7: Grok TTS (your account) | G7: And on the night of the attack, one man ran toward the gunfire. [pause] His story became one of the most shared in the country. [pause] We'll come back to him. | H7: AI voice — disclose in description | I7: FREE SWAP | J7: — | K7: 0 | L7: Not started | N7: Delivery: warm, intriguing
A8: S07 | B8: Atlas | C8: S07_ATLAS.mp3 | D8: S07 | E8: 1:34 | F8: Grok TTS (your account) | G8: None of these threads explains Bondi on its own. [pause] But together, they show the country it happened in. [pause] And to understand that country, we have to follow the money first. | H8: AI voice — disclose in description | I8: FREE SWAP | J8: — | K8: 0 | L8: Not started | N8: Delivery: calm, setting the contract with the viewer
A9: S08 | B9: Ara (backup: Eve) | C9: S08_ARA.mp3 | D9: S08 | E9: 1:54 | F9: Grok TTS (your account) | G9: For months, the fires looked like local crime. But Australia's domestic spy agency, ASIO, kept following the money. [pause] What its investigators found, ASIO's chief later described as a <slow>layer cake.</slow> | H9: AI voice — disclose in description | I9: FREE SWAP | J9: — | K9: 0 | L9: Not started | N9: Delivery: investigative, vivid
A10: S09 | B10: Atlas | C10: S09_ATLAS.mp3 | D10: S09 | E10: 2:09 | F10: Grok TTS (your account) | G10: Middlemen overseas. Coordinators. And at the bottom, local criminals, paid to do a job, not to make a point. [pause] Security experts call it crime as a service. [pause] It's cheap. It's deniable. And it's very hard to detect. | H10: AI voice — disclose in description | I10: FREE SWAP | J10: — | K10: 0 | L10: Not started | N10: Delivery: clear, rhythmic
